Backup failed for Site library-test0. Database or site_config.json may be corrupted
Backup failed for Site library-test0. Database or site_config.json may be corrupted
Traceback (most recent call last):
  File "/Users/andela/Dev/frappe-bench/apps/frappe/frappe/commands/site.py", line 420, in backup
    odb = scheduled_backup(
  File "/Users/andela/Dev/frappe-bench/apps/frappe/frappe/utils/backups.py", line 515, in scheduled_backup
    odb = new_backup(
  File "/Users/andela/Dev/frappe-bench/apps/frappe/frappe/utils/backups.py", line 567, in new_backup
    odb.get_backup(older_than, ignore_files, force=force)
  File "/Users/andela/Dev/frappe-bench/apps/frappe/frappe/utils/backups.py", line 195, in get_backup
    self.take_dump()
  File "/Users/andela/Dev/frappe-bench/apps/frappe/frappe/utils/backups.py", line 354, in take_dump
    frappe.throw(
  File "/Users/andela/Dev/frappe-bench/apps/frappe/frappe/__init__.py", line 433, in throw
    msgprint(msg, raise_exception=exc, title=title, indicator='red', is_minimizable=is_minimizable, wide=wide, as_list=as_list)
  File "/Users/andela/Dev/frappe-bench/apps/frappe/frappe/__init__.py", line 412, in msgprint
    _raise_exception()
  File "/Users/andela/Dev/frappe-bench/apps/frappe/frappe/__init__.py", line 366, in _raise_exception
    raise raise_exception(msg)
frappe.exceptions.ExecutableNotFound: mysqldump not found in PATH! This is required to take a backup.

Traceback (most recent call last):
  File "/Users/andela/Dev/frappe-bench/apps/frappe/frappe/commands/site.py", line 420, in backup
    odb = scheduled_backup(
  File "/Users/andela/Dev/frappe-bench/apps/frappe/frappe/utils/backups.py", line 515, in scheduled_backup
    odb = new_backup(
  File "/Users/andela/Dev/frappe-bench/apps/frappe/frappe/utils/backups.py", line 567, in new_backup
    odb.get_backup(older_than, ignore_files, force=force)
  File "/Users/andela/Dev/frappe-bench/apps/frappe/frappe/utils/backups.py", line 195, in get_backup
    self.take_dump()
  File "/Users/andela/Dev/frappe-bench/apps/frappe/frappe/utils/backups.py", line 354, in take_dump
    frappe.throw(
  File "/Users/andela/Dev/frappe-bench/apps/frappe/frappe/__init__.py", line 433, in throw
    msgprint(msg, raise_exception=exc, title=title, indicator='red', is_minimizable=is_minimizable, wide=wide, as_list=as_list)
  File "/Users/andela/Dev/frappe-bench/apps/frappe/frappe/__init__.py", line 412, in msgprint
    _raise_exception()
  File "/Users/andela/Dev/frappe-bench/apps/frappe/frappe/__init__.py", line 366, in _raise_exception
    raise raise_exception(msg)
frappe.exceptions.ExecutableNotFound: mysqldump not found in PATH! This is required to take a backup.

Backup failed for Site library-test0. Database or site_config.json may be corrupted
Backup failed for Site library-test0. Database or site_config.json may be corrupted
Traceback (most recent call last):
  File "/Users/andela/Dev/frappe-bench/apps/frappe/frappe/commands/site.py", line 420, in backup
    odb = scheduled_backup(
  File "/Users/andela/Dev/frappe-bench/apps/frappe/frappe/utils/backups.py", line 515, in scheduled_backup
    odb = new_backup(
  File "/Users/andela/Dev/frappe-bench/apps/frappe/frappe/utils/backups.py", line 567, in new_backup
    odb.get_backup(older_than, ignore_files, force=force)
  File "/Users/andela/Dev/frappe-bench/apps/frappe/frappe/utils/backups.py", line 195, in get_backup
    self.take_dump()
  File "/Users/andela/Dev/frappe-bench/apps/frappe/frappe/utils/backups.py", line 354, in take_dump
    frappe.throw(
  File "/Users/andela/Dev/frappe-bench/apps/frappe/frappe/__init__.py", line 433, in throw
    msgprint(msg, raise_exception=exc, title=title, indicator='red', is_minimizable=is_minimizable, wide=wide, as_list=as_list)
  File "/Users/andela/Dev/frappe-bench/apps/frappe/frappe/__init__.py", line 412, in msgprint
    _raise_exception()
  File "/Users/andela/Dev/frappe-bench/apps/frappe/frappe/__init__.py", line 366, in _raise_exception
    raise raise_exception(msg)
frappe.exceptions.ExecutableNotFound: mysqldump not found in PATH! This is required to take a backup.

Traceback (most recent call last):
  File "/Users/andela/Dev/frappe-bench/apps/frappe/frappe/commands/site.py", line 420, in backup
    odb = scheduled_backup(
  File "/Users/andela/Dev/frappe-bench/apps/frappe/frappe/utils/backups.py", line 515, in scheduled_backup
    odb = new_backup(
  File "/Users/andela/Dev/frappe-bench/apps/frappe/frappe/utils/backups.py", line 567, in new_backup
    odb.get_backup(older_than, ignore_files, force=force)
  File "/Users/andela/Dev/frappe-bench/apps/frappe/frappe/utils/backups.py", line 195, in get_backup
    self.take_dump()
  File "/Users/andela/Dev/frappe-bench/apps/frappe/frappe/utils/backups.py", line 354, in take_dump
    frappe.throw(
  File "/Users/andela/Dev/frappe-bench/apps/frappe/frappe/__init__.py", line 433, in throw
    msgprint(msg, raise_exception=exc, title=title, indicator='red', is_minimizable=is_minimizable, wide=wide, as_list=as_list)
  File "/Users/andela/Dev/frappe-bench/apps/frappe/frappe/__init__.py", line 412, in msgprint
    _raise_exception()
  File "/Users/andela/Dev/frappe-bench/apps/frappe/frappe/__init__.py", line 366, in _raise_exception
    raise raise_exception(msg)
frappe.exceptions.ExecutableNotFound: mysqldump not found in PATH! This is required to take a backup.

Backup failed for Site contacts_test. Database or site_config.json may be corrupted
Backup failed for Site contacts_test. Database or site_config.json may be corrupted
Traceback (most recent call last):
  File "/Users/andela/Dev/frappe-bench/apps/frappe/frappe/commands/site.py", line 420, in backup
    odb = scheduled_backup(
  File "/Users/andela/Dev/frappe-bench/apps/frappe/frappe/utils/backups.py", line 515, in scheduled_backup
    odb = new_backup(
  File "/Users/andela/Dev/frappe-bench/apps/frappe/frappe/utils/backups.py", line 567, in new_backup
    odb.get_backup(older_than, ignore_files, force=force)
  File "/Users/andela/Dev/frappe-bench/apps/frappe/frappe/utils/backups.py", line 195, in get_backup
    self.take_dump()
  File "/Users/andela/Dev/frappe-bench/apps/frappe/frappe/utils/backups.py", line 354, in take_dump
    frappe.throw(
  File "/Users/andela/Dev/frappe-bench/apps/frappe/frappe/__init__.py", line 433, in throw
    msgprint(msg, raise_exception=exc, title=title, indicator='red', is_minimizable=is_minimizable, wide=wide, as_list=as_list)
  File "/Users/andela/Dev/frappe-bench/apps/frappe/frappe/__init__.py", line 412, in msgprint
    _raise_exception()
  File "/Users/andela/Dev/frappe-bench/apps/frappe/frappe/__init__.py", line 366, in _raise_exception
    raise raise_exception(msg)
frappe.exceptions.ExecutableNotFound: mysqldump not found in PATH! This is required to take a backup.

Backup failed for Site library-test0. Database or site_config.json may be corrupted
Traceback (most recent call last):
  File "/Users/andela/Dev/frappe-bench/apps/frappe/frappe/commands/site.py", line 420, in backup
    odb = scheduled_backup(
  File "/Users/andela/Dev/frappe-bench/apps/frappe/frappe/utils/backups.py", line 515, in scheduled_backup
    odb = new_backup(
  File "/Users/andela/Dev/frappe-bench/apps/frappe/frappe/utils/backups.py", line 567, in new_backup
    odb.get_backup(older_than, ignore_files, force=force)
  File "/Users/andela/Dev/frappe-bench/apps/frappe/frappe/utils/backups.py", line 195, in get_backup
    self.take_dump()
  File "/Users/andela/Dev/frappe-bench/apps/frappe/frappe/utils/backups.py", line 354, in take_dump
    frappe.throw(
  File "/Users/andela/Dev/frappe-bench/apps/frappe/frappe/__init__.py", line 433, in throw
    msgprint(msg, raise_exception=exc, title=title, indicator='red', is_minimizable=is_minimizable, wide=wide, as_list=as_list)
  File "/Users/andela/Dev/frappe-bench/apps/frappe/frappe/__init__.py", line 412, in msgprint
    _raise_exception()
  File "/Users/andela/Dev/frappe-bench/apps/frappe/frappe/__init__.py", line 366, in _raise_exception
    raise raise_exception(msg)
frappe.exceptions.ExecutableNotFound: mysqldump not found in PATH! This is required to take a backup.

Traceback (most recent call last):
  File "/Users/andela/Dev/frappe-bench/apps/frappe/frappe/commands/site.py", line 420, in backup
    odb = scheduled_backup(
  File "/Users/andela/Dev/frappe-bench/apps/frappe/frappe/utils/backups.py", line 515, in scheduled_backup
    odb = new_backup(
  File "/Users/andela/Dev/frappe-bench/apps/frappe/frappe/utils/backups.py", line 567, in new_backup
    odb.get_backup(older_than, ignore_files, force=force)
  File "/Users/andela/Dev/frappe-bench/apps/frappe/frappe/utils/backups.py", line 195, in get_backup
    self.take_dump()
  File "/Users/andela/Dev/frappe-bench/apps/frappe/frappe/utils/backups.py", line 354, in take_dump
    frappe.throw(
  File "/Users/andela/Dev/frappe-bench/apps/frappe/frappe/__init__.py", line 433, in throw
    msgprint(msg, raise_exception=exc, title=title, indicator='red', is_minimizable=is_minimizable, wide=wide, as_list=as_list)
  File "/Users/andela/Dev/frappe-bench/apps/frappe/frappe/__init__.py", line 412, in msgprint
    _raise_exception()
  File "/Users/andela/Dev/frappe-bench/apps/frappe/frappe/__init__.py", line 366, in _raise_exception
    raise raise_exception(msg)
frappe.exceptions.ExecutableNotFound: mysqldump not found in PATH! This is required to take a backup.

Backup failed for Site library-test0. Database or site_config.json may be corrupted
Traceback (most recent call last):
  File "/Users/andela/Dev/frappe-bench/apps/frappe/frappe/commands/site.py", line 420, in backup
    odb = scheduled_backup(
  File "/Users/andela/Dev/frappe-bench/apps/frappe/frappe/utils/backups.py", line 515, in scheduled_backup
    odb = new_backup(
  File "/Users/andela/Dev/frappe-bench/apps/frappe/frappe/utils/backups.py", line 567, in new_backup
    odb.get_backup(older_than, ignore_files, force=force)
  File "/Users/andela/Dev/frappe-bench/apps/frappe/frappe/utils/backups.py", line 195, in get_backup
    self.take_dump()
  File "/Users/andela/Dev/frappe-bench/apps/frappe/frappe/utils/backups.py", line 354, in take_dump
    frappe.throw(
  File "/Users/andela/Dev/frappe-bench/apps/frappe/frappe/__init__.py", line 433, in throw
    msgprint(msg, raise_exception=exc, title=title, indicator='red', is_minimizable=is_minimizable, wide=wide, as_list=as_list)
  File "/Users/andela/Dev/frappe-bench/apps/frappe/frappe/__init__.py", line 412, in msgprint
    _raise_exception()
  File "/Users/andela/Dev/frappe-bench/apps/frappe/frappe/__init__.py", line 366, in _raise_exception
    raise raise_exception(msg)
frappe.exceptions.ExecutableNotFound: mysqldump not found in PATH! This is required to take a backup.

Backup failed for Site contacts_test. Database or site_config.json may be corrupted
Backup failed for Site contacts_test. Database or site_config.json may be corrupted
Traceback (most recent call last):
  File "/Users/andela/Dev/frappe-bench/apps/frappe/frappe/commands/site.py", line 420, in backup
    odb = scheduled_backup(
  File "/Users/andela/Dev/frappe-bench/apps/frappe/frappe/utils/backups.py", line 515, in scheduled_backup
    odb = new_backup(
  File "/Users/andela/Dev/frappe-bench/apps/frappe/frappe/utils/backups.py", line 567, in new_backup
    odb.get_backup(older_than, ignore_files, force=force)
  File "/Users/andela/Dev/frappe-bench/apps/frappe/frappe/utils/backups.py", line 195, in get_backup
    self.take_dump()
  File "/Users/andela/Dev/frappe-bench/apps/frappe/frappe/utils/backups.py", line 354, in take_dump
    frappe.throw(
  File "/Users/andela/Dev/frappe-bench/apps/frappe/frappe/__init__.py", line 433, in throw
    msgprint(msg, raise_exception=exc, title=title, indicator='red', is_minimizable=is_minimizable, wide=wide, as_list=as_list)
  File "/Users/andela/Dev/frappe-bench/apps/frappe/frappe/__init__.py", line 412, in msgprint
    _raise_exception()
  File "/Users/andela/Dev/frappe-bench/apps/frappe/frappe/__init__.py", line 366, in _raise_exception
    raise raise_exception(msg)
frappe.exceptions.ExecutableNotFound: mysqldump not found in PATH! This is required to take a backup.

Backup failed for Site library-test0. Database or site_config.json may be corrupted
Traceback (most recent call last):
  File "/Users/andela/Dev/frappe-bench/apps/frappe/frappe/commands/site.py", line 420, in backup
    odb = scheduled_backup(
  File "/Users/andela/Dev/frappe-bench/apps/frappe/frappe/utils/backups.py", line 515, in scheduled_backup
    odb = new_backup(
  File "/Users/andela/Dev/frappe-bench/apps/frappe/frappe/utils/backups.py", line 567, in new_backup
    odb.get_backup(older_than, ignore_files, force=force)
  File "/Users/andela/Dev/frappe-bench/apps/frappe/frappe/utils/backups.py", line 195, in get_backup
    self.take_dump()
  File "/Users/andela/Dev/frappe-bench/apps/frappe/frappe/utils/backups.py", line 354, in take_dump
    frappe.throw(
  File "/Users/andela/Dev/frappe-bench/apps/frappe/frappe/__init__.py", line 433, in throw
    msgprint(msg, raise_exception=exc, title=title, indicator='red', is_minimizable=is_minimizable, wide=wide, as_list=as_list)
  File "/Users/andela/Dev/frappe-bench/apps/frappe/frappe/__init__.py", line 412, in msgprint
    _raise_exception()
  File "/Users/andela/Dev/frappe-bench/apps/frappe/frappe/__init__.py", line 366, in _raise_exception
    raise raise_exception(msg)
frappe.exceptions.ExecutableNotFound: mysqldump not found in PATH! This is required to take a backup.

Backup failed for Site library-test0. Database or site_config.json may be corrupted
Traceback (most recent call last):
  File "/Users/andela/Dev/frappe-bench/apps/frappe/frappe/commands/site.py", line 420, in backup
    odb = scheduled_backup(
  File "/Users/andela/Dev/frappe-bench/apps/frappe/frappe/utils/backups.py", line 515, in scheduled_backup
    odb = new_backup(
  File "/Users/andela/Dev/frappe-bench/apps/frappe/frappe/utils/backups.py", line 567, in new_backup
    odb.get_backup(older_than, ignore_files, force=force)
  File "/Users/andela/Dev/frappe-bench/apps/frappe/frappe/utils/backups.py", line 195, in get_backup
    self.take_dump()
  File "/Users/andela/Dev/frappe-bench/apps/frappe/frappe/utils/backups.py", line 354, in take_dump
    frappe.throw(
  File "/Users/andela/Dev/frappe-bench/apps/frappe/frappe/__init__.py", line 433, in throw
    msgprint(msg, raise_exception=exc, title=title, indicator='red', is_minimizable=is_minimizable, wide=wide, as_list=as_list)
  File "/Users/andela/Dev/frappe-bench/apps/frappe/frappe/__init__.py", line 412, in msgprint
    _raise_exception()
  File "/Users/andela/Dev/frappe-bench/apps/frappe/frappe/__init__.py", line 366, in _raise_exception
    raise raise_exception(msg)
frappe.exceptions.ExecutableNotFound: mysqldump not found in PATH! This is required to take a backup.

Traceback (most recent call last):
  File "/Users/andela/Dev/frappe-bench/apps/frappe/frappe/commands/site.py", line 420, in backup
    odb = scheduled_backup(
  File "/Users/andela/Dev/frappe-bench/apps/frappe/frappe/utils/backups.py", line 515, in scheduled_backup
    odb = new_backup(
  File "/Users/andela/Dev/frappe-bench/apps/frappe/frappe/utils/backups.py", line 567, in new_backup
    odb.get_backup(older_than, ignore_files, force=force)
  File "/Users/andela/Dev/frappe-bench/apps/frappe/frappe/utils/backups.py", line 195, in get_backup
    self.take_dump()
  File "/Users/andela/Dev/frappe-bench/apps/frappe/frappe/utils/backups.py", line 354, in take_dump
    frappe.throw(
  File "/Users/andela/Dev/frappe-bench/apps/frappe/frappe/__init__.py", line 433, in throw
    msgprint(msg, raise_exception=exc, title=title, indicator='red', is_minimizable=is_minimizable, wide=wide, as_list=as_list)
  File "/Users/andela/Dev/frappe-bench/apps/frappe/frappe/__init__.py", line 412, in msgprint
    _raise_exception()
  File "/Users/andela/Dev/frappe-bench/apps/frappe/frappe/__init__.py", line 366, in _raise_exception
    raise raise_exception(msg)
frappe.exceptions.ExecutableNotFound: mysqldump not found in PATH! This is required to take a backup.

Backup failed for Site contacts_test. Database or site_config.json may be corrupted
Backup failed for Site contacts_test. Database or site_config.json may be corrupted
Traceback (most recent call last):
  File "/Users/andela/Dev/frappe-bench/apps/frappe/frappe/commands/site.py", line 420, in backup
    odb = scheduled_backup(
  File "/Users/andela/Dev/frappe-bench/apps/frappe/frappe/utils/backups.py", line 515, in scheduled_backup
    odb = new_backup(
  File "/Users/andela/Dev/frappe-bench/apps/frappe/frappe/utils/backups.py", line 567, in new_backup
    odb.get_backup(older_than, ignore_files, force=force)
  File "/Users/andela/Dev/frappe-bench/apps/frappe/frappe/utils/backups.py", line 195, in get_backup
    self.take_dump()
  File "/Users/andela/Dev/frappe-bench/apps/frappe/frappe/utils/backups.py", line 354, in take_dump
    frappe.throw(
  File "/Users/andela/Dev/frappe-bench/apps/frappe/frappe/__init__.py", line 433, in throw
    msgprint(msg, raise_exception=exc, title=title, indicator='red', is_minimizable=is_minimizable, wide=wide, as_list=as_list)
  File "/Users/andela/Dev/frappe-bench/apps/frappe/frappe/__init__.py", line 412, in msgprint
    _raise_exception()
  File "/Users/andela/Dev/frappe-bench/apps/frappe/frappe/__init__.py", line 366, in _raise_exception
    raise raise_exception(msg)
frappe.exceptions.ExecutableNotFound: mysqldump not found in PATH! This is required to take a backup.

Backup failed for Site library-test0. Database or site_config.json may be corrupted
Traceback (most recent call last):
  File "/Users/andela/Dev/frappe-bench/apps/frappe/frappe/commands/site.py", line 420, in backup
    odb = scheduled_backup(
  File "/Users/andela/Dev/frappe-bench/apps/frappe/frappe/utils/backups.py", line 515, in scheduled_backup
    odb = new_backup(
  File "/Users/andela/Dev/frappe-bench/apps/frappe/frappe/utils/backups.py", line 567, in new_backup
    odb.get_backup(older_than, ignore_files, force=force)
  File "/Users/andela/Dev/frappe-bench/apps/frappe/frappe/utils/backups.py", line 195, in get_backup
    self.take_dump()
  File "/Users/andela/Dev/frappe-bench/apps/frappe/frappe/utils/backups.py", line 354, in take_dump
    frappe.throw(
  File "/Users/andela/Dev/frappe-bench/apps/frappe/frappe/__init__.py", line 433, in throw
    msgprint(msg, raise_exception=exc, title=title, indicator='red', is_minimizable=is_minimizable, wide=wide, as_list=as_list)
  File "/Users/andela/Dev/frappe-bench/apps/frappe/frappe/__init__.py", line 412, in msgprint
    _raise_exception()
  File "/Users/andela/Dev/frappe-bench/apps/frappe/frappe/__init__.py", line 366, in _raise_exception
    raise raise_exception(msg)
frappe.exceptions.ExecutableNotFound: mysqldump not found in PATH! This is required to take a backup.

Backup failed for Site library-test0. Database or site_config.json may be corrupted
Traceback (most recent call last):
  File "/Users/andela/Dev/frappe-bench/apps/frappe/frappe/commands/site.py", line 420, in backup
    odb = scheduled_backup(
  File "/Users/andela/Dev/frappe-bench/apps/frappe/frappe/utils/backups.py", line 515, in scheduled_backup
    odb = new_backup(
  File "/Users/andela/Dev/frappe-bench/apps/frappe/frappe/utils/backups.py", line 567, in new_backup
    odb.get_backup(older_than, ignore_files, force=force)
  File "/Users/andela/Dev/frappe-bench/apps/frappe/frappe/utils/backups.py", line 195, in get_backup
    self.take_dump()
  File "/Users/andela/Dev/frappe-bench/apps/frappe/frappe/utils/backups.py", line 354, in take_dump
    frappe.throw(
  File "/Users/andela/Dev/frappe-bench/apps/frappe/frappe/__init__.py", line 433, in throw
    msgprint(msg, raise_exception=exc, title=title, indicator='red', is_minimizable=is_minimizable, wide=wide, as_list=as_list)
  File "/Users/andela/Dev/frappe-bench/apps/frappe/frappe/__init__.py", line 412, in msgprint
    _raise_exception()
  File "/Users/andela/Dev/frappe-bench/apps/frappe/frappe/__init__.py", line 366, in _raise_exception
    raise raise_exception(msg)
frappe.exceptions.ExecutableNotFound: mysqldump not found in PATH! This is required to take a backup.

Traceback (most recent call last):
  File "/Users/andela/Dev/frappe-bench/apps/frappe/frappe/commands/site.py", line 420, in backup
    odb = scheduled_backup(
  File "/Users/andela/Dev/frappe-bench/apps/frappe/frappe/utils/backups.py", line 515, in scheduled_backup
    odb = new_backup(
  File "/Users/andela/Dev/frappe-bench/apps/frappe/frappe/utils/backups.py", line 567, in new_backup
    odb.get_backup(older_than, ignore_files, force=force)
  File "/Users/andela/Dev/frappe-bench/apps/frappe/frappe/utils/backups.py", line 195, in get_backup
    self.take_dump()
  File "/Users/andela/Dev/frappe-bench/apps/frappe/frappe/utils/backups.py", line 354, in take_dump
    frappe.throw(
  File "/Users/andela/Dev/frappe-bench/apps/frappe/frappe/__init__.py", line 433, in throw
    msgprint(msg, raise_exception=exc, title=title, indicator='red', is_minimizable=is_minimizable, wide=wide, as_list=as_list)
  File "/Users/andela/Dev/frappe-bench/apps/frappe/frappe/__init__.py", line 412, in msgprint
    _raise_exception()
  File "/Users/andela/Dev/frappe-bench/apps/frappe/frappe/__init__.py", line 366, in _raise_exception
    raise raise_exception(msg)
frappe.exceptions.ExecutableNotFound: mysqldump not found in PATH! This is required to take a backup.

Backup failed for Site contacts_test. Database or site_config.json may be corrupted
Backup failed for Site contacts_test. Database or site_config.json may be corrupted
Traceback (most recent call last):
  File "/Users/andela/Dev/frappe-bench/apps/frappe/frappe/commands/site.py", line 420, in backup
    odb = scheduled_backup(
  File "/Users/andela/Dev/frappe-bench/apps/frappe/frappe/utils/backups.py", line 515, in scheduled_backup
    odb = new_backup(
  File "/Users/andela/Dev/frappe-bench/apps/frappe/frappe/utils/backups.py", line 567, in new_backup
    odb.get_backup(older_than, ignore_files, force=force)
  File "/Users/andela/Dev/frappe-bench/apps/frappe/frappe/utils/backups.py", line 195, in get_backup
    self.take_dump()
  File "/Users/andela/Dev/frappe-bench/apps/frappe/frappe/utils/backups.py", line 354, in take_dump
    frappe.throw(
  File "/Users/andela/Dev/frappe-bench/apps/frappe/frappe/__init__.py", line 433, in throw
    msgprint(msg, raise_exception=exc, title=title, indicator='red', is_minimizable=is_minimizable, wide=wide, as_list=as_list)
  File "/Users/andela/Dev/frappe-bench/apps/frappe/frappe/__init__.py", line 412, in msgprint
    _raise_exception()
  File "/Users/andela/Dev/frappe-bench/apps/frappe/frappe/__init__.py", line 366, in _raise_exception
    raise raise_exception(msg)
frappe.exceptions.ExecutableNotFound: mysqldump not found in PATH! This is required to take a backup.

Backup failed for Site library-test0. Database or site_config.json may be corrupted
Traceback (most recent call last):
  File "/Users/andela/Dev/frappe-bench/apps/frappe/frappe/commands/site.py", line 420, in backup
    odb = scheduled_backup(
  File "/Users/andela/Dev/frappe-bench/apps/frappe/frappe/utils/backups.py", line 515, in scheduled_backup
    odb = new_backup(
  File "/Users/andela/Dev/frappe-bench/apps/frappe/frappe/utils/backups.py", line 567, in new_backup
    odb.get_backup(older_than, ignore_files, force=force)
  File "/Users/andela/Dev/frappe-bench/apps/frappe/frappe/utils/backups.py", line 195, in get_backup
    self.take_dump()
  File "/Users/andela/Dev/frappe-bench/apps/frappe/frappe/utils/backups.py", line 354, in take_dump
    frappe.throw(
  File "/Users/andela/Dev/frappe-bench/apps/frappe/frappe/__init__.py", line 433, in throw
    msgprint(msg, raise_exception=exc, title=title, indicator='red', is_minimizable=is_minimizable, wide=wide, as_list=as_list)
  File "/Users/andela/Dev/frappe-bench/apps/frappe/frappe/__init__.py", line 412, in msgprint
    _raise_exception()
  File "/Users/andela/Dev/frappe-bench/apps/frappe/frappe/__init__.py", line 366, in _raise_exception
    raise raise_exception(msg)
frappe.exceptions.ExecutableNotFound: mysqldump not found in PATH! This is required to take a backup.

Traceback (most recent call last):
  File "/Users/andela/Dev/frappe-bench/apps/frappe/frappe/commands/site.py", line 420, in backup
    odb = scheduled_backup(
  File "/Users/andela/Dev/frappe-bench/apps/frappe/frappe/utils/backups.py", line 515, in scheduled_backup
    odb = new_backup(
  File "/Users/andela/Dev/frappe-bench/apps/frappe/frappe/utils/backups.py", line 567, in new_backup
    odb.get_backup(older_than, ignore_files, force=force)
  File "/Users/andela/Dev/frappe-bench/apps/frappe/frappe/utils/backups.py", line 195, in get_backup
    self.take_dump()
  File "/Users/andela/Dev/frappe-bench/apps/frappe/frappe/utils/backups.py", line 354, in take_dump
    frappe.throw(
  File "/Users/andela/Dev/frappe-bench/apps/frappe/frappe/__init__.py", line 433, in throw
    msgprint(msg, raise_exception=exc, title=title, indicator='red', is_minimizable=is_minimizable, wide=wide, as_list=as_list)
  File "/Users/andela/Dev/frappe-bench/apps/frappe/frappe/__init__.py", line 412, in msgprint
    _raise_exception()
  File "/Users/andela/Dev/frappe-bench/apps/frappe/frappe/__init__.py", line 366, in _raise_exception
    raise raise_exception(msg)
frappe.exceptions.ExecutableNotFound: mysqldump not found in PATH! This is required to take a backup.

Backup failed for Site library-test0. Database or site_config.json may be corrupted
Traceback (most recent call last):
  File "/Users/andela/Dev/frappe-bench/apps/frappe/frappe/commands/site.py", line 420, in backup
    odb = scheduled_backup(
  File "/Users/andela/Dev/frappe-bench/apps/frappe/frappe/utils/backups.py", line 515, in scheduled_backup
    odb = new_backup(
  File "/Users/andela/Dev/frappe-bench/apps/frappe/frappe/utils/backups.py", line 567, in new_backup
    odb.get_backup(older_than, ignore_files, force=force)
  File "/Users/andela/Dev/frappe-bench/apps/frappe/frappe/utils/backups.py", line 195, in get_backup
    self.take_dump()
  File "/Users/andela/Dev/frappe-bench/apps/frappe/frappe/utils/backups.py", line 354, in take_dump
    frappe.throw(
  File "/Users/andela/Dev/frappe-bench/apps/frappe/frappe/__init__.py", line 433, in throw
    msgprint(msg, raise_exception=exc, title=title, indicator='red', is_minimizable=is_minimizable, wide=wide, as_list=as_list)
  File "/Users/andela/Dev/frappe-bench/apps/frappe/frappe/__init__.py", line 412, in msgprint
    _raise_exception()
  File "/Users/andela/Dev/frappe-bench/apps/frappe/frappe/__init__.py", line 366, in _raise_exception
    raise raise_exception(msg)
frappe.exceptions.ExecutableNotFound: mysqldump not found in PATH! This is required to take a backup.

Backup failed for Site contacts_test. Database or site_config.json may be corrupted
Backup failed for Site contacts_test. Database or site_config.json may be corrupted
Traceback (most recent call last):
  File "/Users/andela/Dev/frappe-bench/apps/frappe/frappe/commands/site.py", line 420, in backup
    odb = scheduled_backup(
  File "/Users/andela/Dev/frappe-bench/apps/frappe/frappe/utils/backups.py", line 515, in scheduled_backup
    odb = new_backup(
  File "/Users/andela/Dev/frappe-bench/apps/frappe/frappe/utils/backups.py", line 567, in new_backup
    odb.get_backup(older_than, ignore_files, force=force)
  File "/Users/andela/Dev/frappe-bench/apps/frappe/frappe/utils/backups.py", line 195, in get_backup
    self.take_dump()
  File "/Users/andela/Dev/frappe-bench/apps/frappe/frappe/utils/backups.py", line 354, in take_dump
    frappe.throw(
  File "/Users/andela/Dev/frappe-bench/apps/frappe/frappe/__init__.py", line 433, in throw
    msgprint(msg, raise_exception=exc, title=title, indicator='red', is_minimizable=is_minimizable, wide=wide, as_list=as_list)
  File "/Users/andela/Dev/frappe-bench/apps/frappe/frappe/__init__.py", line 412, in msgprint
    _raise_exception()
  File "/Users/andela/Dev/frappe-bench/apps/frappe/frappe/__init__.py", line 366, in _raise_exception
    raise raise_exception(msg)
frappe.exceptions.ExecutableNotFound: mysqldump not found in PATH! This is required to take a backup.

Backup failed for Site library-test0. Database or site_config.json may be corrupted
Traceback (most recent call last):
  File "/Users/andela/Dev/frappe-bench/apps/frappe/frappe/commands/site.py", line 420, in backup
    odb = scheduled_backup(
  File "/Users/andela/Dev/frappe-bench/apps/frappe/frappe/utils/backups.py", line 515, in scheduled_backup
    odb = new_backup(
  File "/Users/andela/Dev/frappe-bench/apps/frappe/frappe/utils/backups.py", line 567, in new_backup
    odb.get_backup(older_than, ignore_files, force=force)
  File "/Users/andela/Dev/frappe-bench/apps/frappe/frappe/utils/backups.py", line 195, in get_backup
    self.take_dump()
  File "/Users/andela/Dev/frappe-bench/apps/frappe/frappe/utils/backups.py", line 354, in take_dump
    frappe.throw(
  File "/Users/andela/Dev/frappe-bench/apps/frappe/frappe/__init__.py", line 433, in throw
    msgprint(msg, raise_exception=exc, title=title, indicator='red', is_minimizable=is_minimizable, wide=wide, as_list=as_list)
  File "/Users/andela/Dev/frappe-bench/apps/frappe/frappe/__init__.py", line 412, in msgprint
    _raise_exception()
  File "/Users/andela/Dev/frappe-bench/apps/frappe/frappe/__init__.py", line 366, in _raise_exception
    raise raise_exception(msg)
frappe.exceptions.ExecutableNotFound: mysqldump not found in PATH! This is required to take a backup.

Backup failed for Site library-test0. Database or site_config.json may be corrupted
Traceback (most recent call last):
  File "/Users/andela/Dev/frappe-bench/apps/frappe/frappe/commands/site.py", line 420, in backup
    odb = scheduled_backup(
  File "/Users/andela/Dev/frappe-bench/apps/frappe/frappe/utils/backups.py", line 515, in scheduled_backup
    odb = new_backup(
  File "/Users/andela/Dev/frappe-bench/apps/frappe/frappe/utils/backups.py", line 567, in new_backup
    odb.get_backup(older_than, ignore_files, force=force)
  File "/Users/andela/Dev/frappe-bench/apps/frappe/frappe/utils/backups.py", line 195, in get_backup
    self.take_dump()
  File "/Users/andela/Dev/frappe-bench/apps/frappe/frappe/utils/backups.py", line 354, in take_dump
    frappe.throw(
  File "/Users/andela/Dev/frappe-bench/apps/frappe/frappe/__init__.py", line 433, in throw
    msgprint(msg, raise_exception=exc, title=title, indicator='red', is_minimizable=is_minimizable, wide=wide, as_list=as_list)
  File "/Users/andela/Dev/frappe-bench/apps/frappe/frappe/__init__.py", line 412, in msgprint
    _raise_exception()
  File "/Users/andela/Dev/frappe-bench/apps/frappe/frappe/__init__.py", line 366, in _raise_exception
    raise raise_exception(msg)
frappe.exceptions.ExecutableNotFound: mysqldump not found in PATH! This is required to take a backup.

Traceback (most recent call last):
  File "/Users/andela/Dev/frappe-bench/apps/frappe/frappe/commands/site.py", line 420, in backup
    odb = scheduled_backup(
  File "/Users/andela/Dev/frappe-bench/apps/frappe/frappe/utils/backups.py", line 515, in scheduled_backup
    odb = new_backup(
  File "/Users/andela/Dev/frappe-bench/apps/frappe/frappe/utils/backups.py", line 567, in new_backup
    odb.get_backup(older_than, ignore_files, force=force)
  File "/Users/andela/Dev/frappe-bench/apps/frappe/frappe/utils/backups.py", line 195, in get_backup
    self.take_dump()
  File "/Users/andela/Dev/frappe-bench/apps/frappe/frappe/utils/backups.py", line 354, in take_dump
    frappe.throw(
  File "/Users/andela/Dev/frappe-bench/apps/frappe/frappe/__init__.py", line 433, in throw
    msgprint(msg, raise_exception=exc, title=title, indicator='red', is_minimizable=is_minimizable, wide=wide, as_list=as_list)
  File "/Users/andela/Dev/frappe-bench/apps/frappe/frappe/__init__.py", line 412, in msgprint
    _raise_exception()
  File "/Users/andela/Dev/frappe-bench/apps/frappe/frappe/__init__.py", line 366, in _raise_exception
    raise raise_exception(msg)
frappe.exceptions.ExecutableNotFound: mysqldump not found in PATH! This is required to take a backup.

Backup failed for Site company_contacts. Database or site_config.json may be corrupted
Backup failed for Site company_contacts. Database or site_config.json may be corrupted
Traceback (most recent call last):
  File "/Users/andela/Dev/frappe-bench/apps/frappe/frappe/commands/site.py", line 420, in backup
    odb = scheduled_backup(
  File "/Users/andela/Dev/frappe-bench/apps/frappe/frappe/utils/backups.py", line 515, in scheduled_backup
    odb = new_backup(
  File "/Users/andela/Dev/frappe-bench/apps/frappe/frappe/utils/backups.py", line 567, in new_backup
    odb.get_backup(older_than, ignore_files, force=force)
  File "/Users/andela/Dev/frappe-bench/apps/frappe/frappe/utils/backups.py", line 195, in get_backup
    self.take_dump()
  File "/Users/andela/Dev/frappe-bench/apps/frappe/frappe/utils/backups.py", line 354, in take_dump
    frappe.throw(
  File "/Users/andela/Dev/frappe-bench/apps/frappe/frappe/__init__.py", line 433, in throw
    msgprint(msg, raise_exception=exc, title=title, indicator='red', is_minimizable=is_minimizable, wide=wide, as_list=as_list)
  File "/Users/andela/Dev/frappe-bench/apps/frappe/frappe/__init__.py", line 412, in msgprint
    _raise_exception()
  File "/Users/andela/Dev/frappe-bench/apps/frappe/frappe/__init__.py", line 366, in _raise_exception
    raise raise_exception(msg)
frappe.exceptions.ExecutableNotFound: mysqldump not found in PATH! This is required to take a backup.

Backup failed for Site contacts_test. Database or site_config.json may be corrupted
Traceback (most recent call last):
  File "/Users/andela/Dev/frappe-bench/apps/frappe/frappe/commands/site.py", line 420, in backup
    odb = scheduled_backup(
  File "/Users/andela/Dev/frappe-bench/apps/frappe/frappe/utils/backups.py", line 515, in scheduled_backup
    odb = new_backup(
  File "/Users/andela/Dev/frappe-bench/apps/frappe/frappe/utils/backups.py", line 567, in new_backup
    odb.get_backup(older_than, ignore_files, force=force)
  File "/Users/andela/Dev/frappe-bench/apps/frappe/frappe/utils/backups.py", line 195, in get_backup
    self.take_dump()
  File "/Users/andela/Dev/frappe-bench/apps/frappe/frappe/utils/backups.py", line 354, in take_dump
    frappe.throw(
  File "/Users/andela/Dev/frappe-bench/apps/frappe/frappe/__init__.py", line 433, in throw
    msgprint(msg, raise_exception=exc, title=title, indicator='red', is_minimizable=is_minimizable, wide=wide, as_list=as_list)
  File "/Users/andela/Dev/frappe-bench/apps/frappe/frappe/__init__.py", line 412, in msgprint
    _raise_exception()
  File "/Users/andela/Dev/frappe-bench/apps/frappe/frappe/__init__.py", line 366, in _raise_exception
    raise raise_exception(msg)
frappe.exceptions.ExecutableNotFound: mysqldump not found in PATH! This is required to take a backup.

Backup failed for Site contacts_test. Database or site_config.json may be corrupted
Traceback (most recent call last):
  File "/Users/andela/Dev/frappe-bench/apps/frappe/frappe/commands/site.py", line 420, in backup
    odb = scheduled_backup(
  File "/Users/andela/Dev/frappe-bench/apps/frappe/frappe/utils/backups.py", line 515, in scheduled_backup
    odb = new_backup(
  File "/Users/andela/Dev/frappe-bench/apps/frappe/frappe/utils/backups.py", line 567, in new_backup
    odb.get_backup(older_than, ignore_files, force=force)
  File "/Users/andela/Dev/frappe-bench/apps/frappe/frappe/utils/backups.py", line 195, in get_backup
    self.take_dump()
  File "/Users/andela/Dev/frappe-bench/apps/frappe/frappe/utils/backups.py", line 354, in take_dump
    frappe.throw(
  File "/Users/andela/Dev/frappe-bench/apps/frappe/frappe/__init__.py", line 433, in throw
    msgprint(msg, raise_exception=exc, title=title, indicator='red', is_minimizable=is_minimizable, wide=wide, as_list=as_list)
  File "/Users/andela/Dev/frappe-bench/apps/frappe/frappe/__init__.py", line 412, in msgprint
    _raise_exception()
  File "/Users/andela/Dev/frappe-bench/apps/frappe/frappe/__init__.py", line 366, in _raise_exception
    raise raise_exception(msg)
frappe.exceptions.ExecutableNotFound: mysqldump not found in PATH! This is required to take a backup.

Backup failed for Site library-test0. Database or site_config.json may be corrupted
Traceback (most recent call last):
  File "/Users/andela/Dev/frappe-bench/apps/frappe/frappe/commands/site.py", line 420, in backup
    odb = scheduled_backup(
  File "/Users/andela/Dev/frappe-bench/apps/frappe/frappe/utils/backups.py", line 515, in scheduled_backup
    odb = new_backup(
  File "/Users/andela/Dev/frappe-bench/apps/frappe/frappe/utils/backups.py", line 567, in new_backup
    odb.get_backup(older_than, ignore_files, force=force)
  File "/Users/andela/Dev/frappe-bench/apps/frappe/frappe/utils/backups.py", line 195, in get_backup
    self.take_dump()
  File "/Users/andela/Dev/frappe-bench/apps/frappe/frappe/utils/backups.py", line 354, in take_dump
    frappe.throw(
  File "/Users/andela/Dev/frappe-bench/apps/frappe/frappe/__init__.py", line 433, in throw
    msgprint(msg, raise_exception=exc, title=title, indicator='red', is_minimizable=is_minimizable, wide=wide, as_list=as_list)
  File "/Users/andela/Dev/frappe-bench/apps/frappe/frappe/__init__.py", line 412, in msgprint
    _raise_exception()
  File "/Users/andela/Dev/frappe-bench/apps/frappe/frappe/__init__.py", line 366, in _raise_exception
    raise raise_exception(msg)
frappe.exceptions.ExecutableNotFound: mysqldump not found in PATH! This is required to take a backup.

Traceback (most recent call last):
  File "/Users/andela/Dev/frappe-bench/apps/frappe/frappe/commands/site.py", line 420, in backup
    odb = scheduled_backup(
  File "/Users/andela/Dev/frappe-bench/apps/frappe/frappe/utils/backups.py", line 515, in scheduled_backup
    odb = new_backup(
  File "/Users/andela/Dev/frappe-bench/apps/frappe/frappe/utils/backups.py", line 567, in new_backup
    odb.get_backup(older_than, ignore_files, force=force)
  File "/Users/andela/Dev/frappe-bench/apps/frappe/frappe/utils/backups.py", line 195, in get_backup
    self.take_dump()
  File "/Users/andela/Dev/frappe-bench/apps/frappe/frappe/utils/backups.py", line 354, in take_dump
    frappe.throw(
  File "/Users/andela/Dev/frappe-bench/apps/frappe/frappe/__init__.py", line 433, in throw
    msgprint(msg, raise_exception=exc, title=title, indicator='red', is_minimizable=is_minimizable, wide=wide, as_list=as_list)
  File "/Users/andela/Dev/frappe-bench/apps/frappe/frappe/__init__.py", line 412, in msgprint
    _raise_exception()
  File "/Users/andela/Dev/frappe-bench/apps/frappe/frappe/__init__.py", line 366, in _raise_exception
    raise raise_exception(msg)
frappe.exceptions.ExecutableNotFound: mysqldump not found in PATH! This is required to take a backup.

Backup failed for Site library-test0. Database or site_config.json may be corrupted
Traceback (most recent call last):
  File "/Users/andela/Dev/frappe-bench/apps/frappe/frappe/commands/site.py", line 420, in backup
    odb = scheduled_backup(
  File "/Users/andela/Dev/frappe-bench/apps/frappe/frappe/utils/backups.py", line 515, in scheduled_backup
    odb = new_backup(
  File "/Users/andela/Dev/frappe-bench/apps/frappe/frappe/utils/backups.py", line 567, in new_backup
    odb.get_backup(older_than, ignore_files, force=force)
  File "/Users/andela/Dev/frappe-bench/apps/frappe/frappe/utils/backups.py", line 195, in get_backup
    self.take_dump()
  File "/Users/andela/Dev/frappe-bench/apps/frappe/frappe/utils/backups.py", line 354, in take_dump
    frappe.throw(
  File "/Users/andela/Dev/frappe-bench/apps/frappe/frappe/__init__.py", line 433, in throw
    msgprint(msg, raise_exception=exc, title=title, indicator='red', is_minimizable=is_minimizable, wide=wide, as_list=as_list)
  File "/Users/andela/Dev/frappe-bench/apps/frappe/frappe/__init__.py", line 412, in msgprint
    _raise_exception()
  File "/Users/andela/Dev/frappe-bench/apps/frappe/frappe/__init__.py", line 366, in _raise_exception
    raise raise_exception(msg)
frappe.exceptions.ExecutableNotFound: mysqldump not found in PATH! This is required to take a backup.

Backup failed for Site company_contacts. Database or site_config.json may be corrupted
Backup failed for Site company_contacts. Database or site_config.json may be corrupted
Traceback (most recent call last):
  File "/Users/andela/Dev/frappe-bench/apps/frappe/frappe/commands/site.py", line 420, in backup
    odb = scheduled_backup(
  File "/Users/andela/Dev/frappe-bench/apps/frappe/frappe/utils/backups.py", line 515, in scheduled_backup
    odb = new_backup(
  File "/Users/andela/Dev/frappe-bench/apps/frappe/frappe/utils/backups.py", line 567, in new_backup
    odb.get_backup(older_than, ignore_files, force=force)
  File "/Users/andela/Dev/frappe-bench/apps/frappe/frappe/utils/backups.py", line 195, in get_backup
    self.take_dump()
  File "/Users/andela/Dev/frappe-bench/apps/frappe/frappe/utils/backups.py", line 354, in take_dump
    frappe.throw(
  File "/Users/andela/Dev/frappe-bench/apps/frappe/frappe/__init__.py", line 433, in throw
    msgprint(msg, raise_exception=exc, title=title, indicator='red', is_minimizable=is_minimizable, wide=wide, as_list=as_list)
  File "/Users/andela/Dev/frappe-bench/apps/frappe/frappe/__init__.py", line 412, in msgprint
    _raise_exception()
  File "/Users/andela/Dev/frappe-bench/apps/frappe/frappe/__init__.py", line 366, in _raise_exception
    raise raise_exception(msg)
frappe.exceptions.ExecutableNotFound: mysqldump not found in PATH! This is required to take a backup.

Backup failed for Site contacts_test. Database or site_config.json may be corrupted
Traceback (most recent call last):
  File "/Users/andela/Dev/frappe-bench/apps/frappe/frappe/commands/site.py", line 420, in backup
    odb = scheduled_backup(
  File "/Users/andela/Dev/frappe-bench/apps/frappe/frappe/utils/backups.py", line 515, in scheduled_backup
    odb = new_backup(
  File "/Users/andela/Dev/frappe-bench/apps/frappe/frappe/utils/backups.py", line 567, in new_backup
    odb.get_backup(older_than, ignore_files, force=force)
  File "/Users/andela/Dev/frappe-bench/apps/frappe/frappe/utils/backups.py", line 195, in get_backup
    self.take_dump()
  File "/Users/andela/Dev/frappe-bench/apps/frappe/frappe/utils/backups.py", line 354, in take_dump
    frappe.throw(
  File "/Users/andela/Dev/frappe-bench/apps/frappe/frappe/__init__.py", line 433, in throw
    msgprint(msg, raise_exception=exc, title=title, indicator='red', is_minimizable=is_minimizable, wide=wide, as_list=as_list)
  File "/Users/andela/Dev/frappe-bench/apps/frappe/frappe/__init__.py", line 412, in msgprint
    _raise_exception()
  File "/Users/andela/Dev/frappe-bench/apps/frappe/frappe/__init__.py", line 366, in _raise_exception
    raise raise_exception(msg)
frappe.exceptions.ExecutableNotFound: mysqldump not found in PATH! This is required to take a backup.

Backup failed for Site contacts_test. Database or site_config.json may be corrupted
Traceback (most recent call last):
  File "/Users/andela/Dev/frappe-bench/apps/frappe/frappe/commands/site.py", line 420, in backup
    odb = scheduled_backup(
  File "/Users/andela/Dev/frappe-bench/apps/frappe/frappe/utils/backups.py", line 515, in scheduled_backup
    odb = new_backup(
  File "/Users/andela/Dev/frappe-bench/apps/frappe/frappe/utils/backups.py", line 567, in new_backup
    odb.get_backup(older_than, ignore_files, force=force)
  File "/Users/andela/Dev/frappe-bench/apps/frappe/frappe/utils/backups.py", line 195, in get_backup
    self.take_dump()
  File "/Users/andela/Dev/frappe-bench/apps/frappe/frappe/utils/backups.py", line 354, in take_dump
    frappe.throw(
  File "/Users/andela/Dev/frappe-bench/apps/frappe/frappe/__init__.py", line 433, in throw
    msgprint(msg, raise_exception=exc, title=title, indicator='red', is_minimizable=is_minimizable, wide=wide, as_list=as_list)
  File "/Users/andela/Dev/frappe-bench/apps/frappe/frappe/__init__.py", line 412, in msgprint
    _raise_exception()
  File "/Users/andela/Dev/frappe-bench/apps/frappe/frappe/__init__.py", line 366, in _raise_exception
    raise raise_exception(msg)
frappe.exceptions.ExecutableNotFound: mysqldump not found in PATH! This is required to take a backup.

Backup failed for Site library-test0. Database or site_config.json may be corrupted
Traceback (most recent call last):
  File "/Users/andela/Dev/frappe-bench/apps/frappe/frappe/commands/site.py", line 420, in backup
    odb = scheduled_backup(
  File "/Users/andela/Dev/frappe-bench/apps/frappe/frappe/utils/backups.py", line 515, in scheduled_backup
    odb = new_backup(
  File "/Users/andela/Dev/frappe-bench/apps/frappe/frappe/utils/backups.py", line 567, in new_backup
    odb.get_backup(older_than, ignore_files, force=force)
  File "/Users/andela/Dev/frappe-bench/apps/frappe/frappe/utils/backups.py", line 195, in get_backup
    self.take_dump()
  File "/Users/andela/Dev/frappe-bench/apps/frappe/frappe/utils/backups.py", line 354, in take_dump
    frappe.throw(
  File "/Users/andela/Dev/frappe-bench/apps/frappe/frappe/__init__.py", line 433, in throw
    msgprint(msg, raise_exception=exc, title=title, indicator='red', is_minimizable=is_minimizable, wide=wide, as_list=as_list)
  File "/Users/andela/Dev/frappe-bench/apps/frappe/frappe/__init__.py", line 412, in msgprint
    _raise_exception()
  File "/Users/andela/Dev/frappe-bench/apps/frappe/frappe/__init__.py", line 366, in _raise_exception
    raise raise_exception(msg)
frappe.exceptions.ExecutableNotFound: mysqldump not found in PATH! This is required to take a backup.

Traceback (most recent call last):
  File "/Users/andela/Dev/frappe-bench/apps/frappe/frappe/commands/site.py", line 420, in backup
    odb = scheduled_backup(
  File "/Users/andela/Dev/frappe-bench/apps/frappe/frappe/utils/backups.py", line 515, in scheduled_backup
    odb = new_backup(
  File "/Users/andela/Dev/frappe-bench/apps/frappe/frappe/utils/backups.py", line 567, in new_backup
    odb.get_backup(older_than, ignore_files, force=force)
  File "/Users/andela/Dev/frappe-bench/apps/frappe/frappe/utils/backups.py", line 195, in get_backup
    self.take_dump()
  File "/Users/andela/Dev/frappe-bench/apps/frappe/frappe/utils/backups.py", line 354, in take_dump
    frappe.throw(
  File "/Users/andela/Dev/frappe-bench/apps/frappe/frappe/__init__.py", line 433, in throw
    msgprint(msg, raise_exception=exc, title=title, indicator='red', is_minimizable=is_minimizable, wide=wide, as_list=as_list)
  File "/Users/andela/Dev/frappe-bench/apps/frappe/frappe/__init__.py", line 412, in msgprint
    _raise_exception()
  File "/Users/andela/Dev/frappe-bench/apps/frappe/frappe/__init__.py", line 366, in _raise_exception
    raise raise_exception(msg)
frappe.exceptions.ExecutableNotFound: mysqldump not found in PATH! This is required to take a backup.

Backup failed for Site library-test0. Database or site_config.json may be corrupted
Traceback (most recent call last):
  File "/Users/andela/Dev/frappe-bench/apps/frappe/frappe/commands/site.py", line 420, in backup
    odb = scheduled_backup(
  File "/Users/andela/Dev/frappe-bench/apps/frappe/frappe/utils/backups.py", line 515, in scheduled_backup
    odb = new_backup(
  File "/Users/andela/Dev/frappe-bench/apps/frappe/frappe/utils/backups.py", line 567, in new_backup
    odb.get_backup(older_than, ignore_files, force=force)
  File "/Users/andela/Dev/frappe-bench/apps/frappe/frappe/utils/backups.py", line 195, in get_backup
    self.take_dump()
  File "/Users/andela/Dev/frappe-bench/apps/frappe/frappe/utils/backups.py", line 354, in take_dump
    frappe.throw(
  File "/Users/andela/Dev/frappe-bench/apps/frappe/frappe/__init__.py", line 433, in throw
    msgprint(msg, raise_exception=exc, title=title, indicator='red', is_minimizable=is_minimizable, wide=wide, as_list=as_list)
  File "/Users/andela/Dev/frappe-bench/apps/frappe/frappe/__init__.py", line 412, in msgprint
    _raise_exception()
  File "/Users/andela/Dev/frappe-bench/apps/frappe/frappe/__init__.py", line 366, in _raise_exception
    raise raise_exception(msg)
frappe.exceptions.ExecutableNotFound: mysqldump not found in PATH! This is required to take a backup.

Backup failed for Site company_contacts. Database or site_config.json may be corrupted
Backup failed for Site company_contacts. Database or site_config.json may be corrupted
Traceback (most recent call last):
  File "/Users/andela/Dev/frappe-bench/apps/frappe/frappe/commands/site.py", line 420, in backup
    odb = scheduled_backup(
  File "/Users/andela/Dev/frappe-bench/apps/frappe/frappe/utils/backups.py", line 515, in scheduled_backup
    odb = new_backup(
  File "/Users/andela/Dev/frappe-bench/apps/frappe/frappe/utils/backups.py", line 567, in new_backup
    odb.get_backup(older_than, ignore_files, force=force)
  File "/Users/andela/Dev/frappe-bench/apps/frappe/frappe/utils/backups.py", line 195, in get_backup
    self.take_dump()
  File "/Users/andela/Dev/frappe-bench/apps/frappe/frappe/utils/backups.py", line 354, in take_dump
    frappe.throw(
  File "/Users/andela/Dev/frappe-bench/apps/frappe/frappe/__init__.py", line 433, in throw
    msgprint(msg, raise_exception=exc, title=title, indicator='red', is_minimizable=is_minimizable, wide=wide, as_list=as_list)
  File "/Users/andela/Dev/frappe-bench/apps/frappe/frappe/__init__.py", line 412, in msgprint
    _raise_exception()
  File "/Users/andela/Dev/frappe-bench/apps/frappe/frappe/__init__.py", line 366, in _raise_exception
    raise raise_exception(msg)
frappe.exceptions.ExecutableNotFound: mysqldump not found in PATH! This is required to take a backup.

Backup failed for Site contacts_test. Database or site_config.json may be corrupted
Traceback (most recent call last):
  File "/Users/andela/Dev/frappe-bench/apps/frappe/frappe/commands/site.py", line 420, in backup
    odb = scheduled_backup(
  File "/Users/andela/Dev/frappe-bench/apps/frappe/frappe/utils/backups.py", line 515, in scheduled_backup
    odb = new_backup(
  File "/Users/andela/Dev/frappe-bench/apps/frappe/frappe/utils/backups.py", line 567, in new_backup
    odb.get_backup(older_than, ignore_files, force=force)
  File "/Users/andela/Dev/frappe-bench/apps/frappe/frappe/utils/backups.py", line 195, in get_backup
    self.take_dump()
  File "/Users/andela/Dev/frappe-bench/apps/frappe/frappe/utils/backups.py", line 354, in take_dump
    frappe.throw(
  File "/Users/andela/Dev/frappe-bench/apps/frappe/frappe/__init__.py", line 433, in throw
    msgprint(msg, raise_exception=exc, title=title, indicator='red', is_minimizable=is_minimizable, wide=wide, as_list=as_list)
  File "/Users/andela/Dev/frappe-bench/apps/frappe/frappe/__init__.py", line 412, in msgprint
    _raise_exception()
  File "/Users/andela/Dev/frappe-bench/apps/frappe/frappe/__init__.py", line 366, in _raise_exception
    raise raise_exception(msg)
frappe.exceptions.ExecutableNotFound: mysqldump not found in PATH! This is required to take a backup.

Backup failed for Site contacts_test. Database or site_config.json may be corrupted
Traceback (most recent call last):
  File "/Users/andela/Dev/frappe-bench/apps/frappe/frappe/commands/site.py", line 420, in backup
    odb = scheduled_backup(
  File "/Users/andela/Dev/frappe-bench/apps/frappe/frappe/utils/backups.py", line 515, in scheduled_backup
    odb = new_backup(
  File "/Users/andela/Dev/frappe-bench/apps/frappe/frappe/utils/backups.py", line 567, in new_backup
    odb.get_backup(older_than, ignore_files, force=force)
  File "/Users/andela/Dev/frappe-bench/apps/frappe/frappe/utils/backups.py", line 195, in get_backup
    self.take_dump()
  File "/Users/andela/Dev/frappe-bench/apps/frappe/frappe/utils/backups.py", line 354, in take_dump
    frappe.throw(
  File "/Users/andela/Dev/frappe-bench/apps/frappe/frappe/__init__.py", line 433, in throw
    msgprint(msg, raise_exception=exc, title=title, indicator='red', is_minimizable=is_minimizable, wide=wide, as_list=as_list)
  File "/Users/andela/Dev/frappe-bench/apps/frappe/frappe/__init__.py", line 412, in msgprint
    _raise_exception()
  File "/Users/andela/Dev/frappe-bench/apps/frappe/frappe/__init__.py", line 366, in _raise_exception
    raise raise_exception(msg)
frappe.exceptions.ExecutableNotFound: mysqldump not found in PATH! This is required to take a backup.

Backup failed for Site library-test0. Database or site_config.json may be corrupted
Traceback (most recent call last):
  File "/Users/andela/Dev/frappe-bench/apps/frappe/frappe/commands/site.py", line 420, in backup
    odb = scheduled_backup(
  File "/Users/andela/Dev/frappe-bench/apps/frappe/frappe/utils/backups.py", line 515, in scheduled_backup
    odb = new_backup(
  File "/Users/andela/Dev/frappe-bench/apps/frappe/frappe/utils/backups.py", line 567, in new_backup
    odb.get_backup(older_than, ignore_files, force=force)
  File "/Users/andela/Dev/frappe-bench/apps/frappe/frappe/utils/backups.py", line 195, in get_backup
    self.take_dump()
  File "/Users/andela/Dev/frappe-bench/apps/frappe/frappe/utils/backups.py", line 354, in take_dump
    frappe.throw(
  File "/Users/andela/Dev/frappe-bench/apps/frappe/frappe/__init__.py", line 433, in throw
    msgprint(msg, raise_exception=exc, title=title, indicator='red', is_minimizable=is_minimizable, wide=wide, as_list=as_list)
  File "/Users/andela/Dev/frappe-bench/apps/frappe/frappe/__init__.py", line 412, in msgprint
    _raise_exception()
  File "/Users/andela/Dev/frappe-bench/apps/frappe/frappe/__init__.py", line 366, in _raise_exception
    raise raise_exception(msg)
frappe.exceptions.ExecutableNotFound: mysqldump not found in PATH! This is required to take a backup.

Traceback (most recent call last):
  File "/Users/andela/Dev/frappe-bench/apps/frappe/frappe/commands/site.py", line 420, in backup
    odb = scheduled_backup(
  File "/Users/andela/Dev/frappe-bench/apps/frappe/frappe/utils/backups.py", line 515, in scheduled_backup
    odb = new_backup(
  File "/Users/andela/Dev/frappe-bench/apps/frappe/frappe/utils/backups.py", line 567, in new_backup
    odb.get_backup(older_than, ignore_files, force=force)
  File "/Users/andela/Dev/frappe-bench/apps/frappe/frappe/utils/backups.py", line 195, in get_backup
    self.take_dump()
  File "/Users/andela/Dev/frappe-bench/apps/frappe/frappe/utils/backups.py", line 354, in take_dump
    frappe.throw(
  File "/Users/andela/Dev/frappe-bench/apps/frappe/frappe/__init__.py", line 433, in throw
    msgprint(msg, raise_exception=exc, title=title, indicator='red', is_minimizable=is_minimizable, wide=wide, as_list=as_list)
  File "/Users/andela/Dev/frappe-bench/apps/frappe/frappe/__init__.py", line 412, in msgprint
    _raise_exception()
  File "/Users/andela/Dev/frappe-bench/apps/frappe/frappe/__init__.py", line 366, in _raise_exception
    raise raise_exception(msg)
frappe.exceptions.ExecutableNotFound: mysqldump not found in PATH! This is required to take a backup.

Backup failed for Site library-test0. Database or site_config.json may be corrupted
Traceback (most recent call last):
  File "/Users/andela/Dev/frappe-bench/apps/frappe/frappe/commands/site.py", line 420, in backup
    odb = scheduled_backup(
  File "/Users/andela/Dev/frappe-bench/apps/frappe/frappe/utils/backups.py", line 515, in scheduled_backup
    odb = new_backup(
  File "/Users/andela/Dev/frappe-bench/apps/frappe/frappe/utils/backups.py", line 567, in new_backup
    odb.get_backup(older_than, ignore_files, force=force)
  File "/Users/andela/Dev/frappe-bench/apps/frappe/frappe/utils/backups.py", line 195, in get_backup
    self.take_dump()
  File "/Users/andela/Dev/frappe-bench/apps/frappe/frappe/utils/backups.py", line 354, in take_dump
    frappe.throw(
  File "/Users/andela/Dev/frappe-bench/apps/frappe/frappe/__init__.py", line 433, in throw
    msgprint(msg, raise_exception=exc, title=title, indicator='red', is_minimizable=is_minimizable, wide=wide, as_list=as_list)
  File "/Users/andela/Dev/frappe-bench/apps/frappe/frappe/__init__.py", line 412, in msgprint
    _raise_exception()
  File "/Users/andela/Dev/frappe-bench/apps/frappe/frappe/__init__.py", line 366, in _raise_exception
    raise raise_exception(msg)
frappe.exceptions.ExecutableNotFound: mysqldump not found in PATH! This is required to take a backup.

Backup failed for Site contacts_test. Database or site_config.json may be corrupted
Backup failed for Site contacts_test. Database or site_config.json may be corrupted
Traceback (most recent call last):
  File "/Users/andela/Dev/frappe-bench/apps/frappe/frappe/commands/site.py", line 429, in backup
    odb = scheduled_backup(
  File "/Users/andela/Dev/frappe-bench/apps/frappe/frappe/utils/backups.py", line 515, in scheduled_backup
    odb = new_backup(
  File "/Users/andela/Dev/frappe-bench/apps/frappe/frappe/utils/backups.py", line 567, in new_backup
    odb.get_backup(older_than, ignore_files, force=force)
  File "/Users/andela/Dev/frappe-bench/apps/frappe/frappe/utils/backups.py", line 195, in get_backup
    self.take_dump()
  File "/Users/andela/Dev/frappe-bench/apps/frappe/frappe/utils/backups.py", line 354, in take_dump
    frappe.throw(
  File "/Users/andela/Dev/frappe-bench/apps/frappe/frappe/__init__.py", line 427, in throw
    msgprint(msg, raise_exception=exc, title=title, indicator='red', is_minimizable=is_minimizable, wide=wide, as_list=as_list)
  File "/Users/andela/Dev/frappe-bench/apps/frappe/frappe/__init__.py", line 406, in msgprint
    _raise_exception()
  File "/Users/andela/Dev/frappe-bench/apps/frappe/frappe/__init__.py", line 360, in _raise_exception
    raise raise_exception(msg)
frappe.exceptions.ExecutableNotFound: mysqldump not found in PATH! This is required to take a backup.

File ./contacts_test/private/backups/20210505_150938-contacts_test-database.sql.gz is recent
File ./contacts_test/private/backups/20210505_150938-contacts_test-site_config_backup.json is recent
Backup failed for Site library-test0. Database or site_config.json may be corrupted
Traceback (most recent call last):
  File "/Users/andela/Dev/frappe-bench/apps/frappe/frappe/commands/site.py", line 429, in backup
    odb = scheduled_backup(
  File "/Users/andela/Dev/frappe-bench/apps/frappe/frappe/utils/backups.py", line 515, in scheduled_backup
    odb = new_backup(
  File "/Users/andela/Dev/frappe-bench/apps/frappe/frappe/utils/backups.py", line 567, in new_backup
    odb.get_backup(older_than, ignore_files, force=force)
  File "/Users/andela/Dev/frappe-bench/apps/frappe/frappe/utils/backups.py", line 195, in get_backup
    self.take_dump()
  File "/Users/andela/Dev/frappe-bench/apps/frappe/frappe/utils/backups.py", line 354, in take_dump
    frappe.throw(
  File "/Users/andela/Dev/frappe-bench/apps/frappe/frappe/__init__.py", line 427, in throw
    msgprint(msg, raise_exception=exc, title=title, indicator='red', is_minimizable=is_minimizable, wide=wide, as_list=as_list)
  File "/Users/andela/Dev/frappe-bench/apps/frappe/frappe/__init__.py", line 406, in msgprint
    _raise_exception()
  File "/Users/andela/Dev/frappe-bench/apps/frappe/frappe/__init__.py", line 360, in _raise_exception
    raise raise_exception(msg)
frappe.exceptions.ExecutableNotFound: mysqldump not found in PATH! This is required to take a backup.

File ./contacts_test/private/backups/20210505_150938-contacts_test-database.sql.gz is recent
File ./contacts_test/private/backups/20210505_150938-contacts_test-site_config_backup.json is recent
Backup failed for Site library-test0. Database or site_config.json may be corrupted
Traceback (most recent call last):
  File "/Users/andela/Dev/frappe-bench/apps/frappe/frappe/commands/site.py", line 429, in backup
    odb = scheduled_backup(
  File "/Users/andela/Dev/frappe-bench/apps/frappe/frappe/utils/backups.py", line 515, in scheduled_backup
    odb = new_backup(
  File "/Users/andela/Dev/frappe-bench/apps/frappe/frappe/utils/backups.py", line 567, in new_backup
    odb.get_backup(older_than, ignore_files, force=force)
  File "/Users/andela/Dev/frappe-bench/apps/frappe/frappe/utils/backups.py", line 195, in get_backup
    self.take_dump()
  File "/Users/andela/Dev/frappe-bench/apps/frappe/frappe/utils/backups.py", line 354, in take_dump
    frappe.throw(
  File "/Users/andela/Dev/frappe-bench/apps/frappe/frappe/__init__.py", line 427, in throw
    msgprint(msg, raise_exception=exc, title=title, indicator='red', is_minimizable=is_minimizable, wide=wide, as_list=as_list)
  File "/Users/andela/Dev/frappe-bench/apps/frappe/frappe/__init__.py", line 406, in msgprint
    _raise_exception()
  File "/Users/andela/Dev/frappe-bench/apps/frappe/frappe/__init__.py", line 360, in _raise_exception
    raise raise_exception(msg)
frappe.exceptions.ExecutableNotFound: mysqldump not found in PATH! This is required to take a backup.

Traceback (most recent call last):
  File "/Users/andela/Dev/frappe-bench/apps/frappe/frappe/commands/site.py", line 429, in backup
    odb = scheduled_backup(
  File "/Users/andela/Dev/frappe-bench/apps/frappe/frappe/utils/backups.py", line 515, in scheduled_backup
    odb = new_backup(
  File "/Users/andela/Dev/frappe-bench/apps/frappe/frappe/utils/backups.py", line 567, in new_backup
    odb.get_backup(older_than, ignore_files, force=force)
  File "/Users/andela/Dev/frappe-bench/apps/frappe/frappe/utils/backups.py", line 195, in get_backup
    self.take_dump()
  File "/Users/andela/Dev/frappe-bench/apps/frappe/frappe/utils/backups.py", line 354, in take_dump
    frappe.throw(
  File "/Users/andela/Dev/frappe-bench/apps/frappe/frappe/__init__.py", line 427, in throw
    msgprint(msg, raise_exception=exc, title=title, indicator='red', is_minimizable=is_minimizable, wide=wide, as_list=as_list)
  File "/Users/andela/Dev/frappe-bench/apps/frappe/frappe/__init__.py", line 406, in msgprint
    _raise_exception()
  File "/Users/andela/Dev/frappe-bench/apps/frappe/frappe/__init__.py", line 360, in _raise_exception
    raise raise_exception(msg)
frappe.exceptions.ExecutableNotFound: mysqldump not found in PATH! This is required to take a backup.

Backup failed for Site contacts_test. Database or site_config.json may be corrupted
Backup failed for Site contacts_test. Database or site_config.json may be corrupted
Traceback (most recent call last):
  File "/Users/andela/Dev/frappe-bench/apps/frappe/frappe/commands/site.py", line 429, in backup
    odb = scheduled_backup(
  File "/Users/andela/Dev/frappe-bench/apps/frappe/frappe/utils/backups.py", line 515, in scheduled_backup
    odb = new_backup(
  File "/Users/andela/Dev/frappe-bench/apps/frappe/frappe/utils/backups.py", line 567, in new_backup
    odb.get_backup(older_than, ignore_files, force=force)
  File "/Users/andela/Dev/frappe-bench/apps/frappe/frappe/utils/backups.py", line 195, in get_backup
    self.take_dump()
  File "/Users/andela/Dev/frappe-bench/apps/frappe/frappe/utils/backups.py", line 354, in take_dump
    frappe.throw(
  File "/Users/andela/Dev/frappe-bench/apps/frappe/frappe/__init__.py", line 427, in throw
    msgprint(msg, raise_exception=exc, title=title, indicator='red', is_minimizable=is_minimizable, wide=wide, as_list=as_list)
  File "/Users/andela/Dev/frappe-bench/apps/frappe/frappe/__init__.py", line 406, in msgprint
    _raise_exception()
  File "/Users/andela/Dev/frappe-bench/apps/frappe/frappe/__init__.py", line 360, in _raise_exception
    raise raise_exception(msg)
frappe.exceptions.ExecutableNotFound: mysqldump not found in PATH! This is required to take a backup.

File ./contacts_test/private/backups/20210505_150938-contacts_test-database.sql.gz is recent
File ./contacts_test/private/backups/20210505_150938-contacts_test-site_config_backup.json is recent
Backup failed for Site library-test0. Database or site_config.json may be corrupted
Traceback (most recent call last):
  File "/Users/andela/Dev/frappe-bench/apps/frappe/frappe/commands/site.py", line 429, in backup
    odb = scheduled_backup(
  File "/Users/andela/Dev/frappe-bench/apps/frappe/frappe/utils/backups.py", line 515, in scheduled_backup
    odb = new_backup(
  File "/Users/andela/Dev/frappe-bench/apps/frappe/frappe/utils/backups.py", line 567, in new_backup
    odb.get_backup(older_than, ignore_files, force=force)
  File "/Users/andela/Dev/frappe-bench/apps/frappe/frappe/utils/backups.py", line 195, in get_backup
    self.take_dump()
  File "/Users/andela/Dev/frappe-bench/apps/frappe/frappe/utils/backups.py", line 354, in take_dump
    frappe.throw(
  File "/Users/andela/Dev/frappe-bench/apps/frappe/frappe/__init__.py", line 427, in throw
    msgprint(msg, raise_exception=exc, title=title, indicator='red', is_minimizable=is_minimizable, wide=wide, as_list=as_list)
  File "/Users/andela/Dev/frappe-bench/apps/frappe/frappe/__init__.py", line 406, in msgprint
    _raise_exception()
  File "/Users/andela/Dev/frappe-bench/apps/frappe/frappe/__init__.py", line 360, in _raise_exception
    raise raise_exception(msg)
frappe.exceptions.ExecutableNotFound: mysqldump not found in PATH! This is required to take a backup.

Traceback (most recent call last):
  File "/Users/andela/Dev/frappe-bench/apps/frappe/frappe/commands/site.py", line 429, in backup
    odb = scheduled_backup(
  File "/Users/andela/Dev/frappe-bench/apps/frappe/frappe/utils/backups.py", line 515, in scheduled_backup
    odb = new_backup(
  File "/Users/andela/Dev/frappe-bench/apps/frappe/frappe/utils/backups.py", line 567, in new_backup
    odb.get_backup(older_than, ignore_files, force=force)
  File "/Users/andela/Dev/frappe-bench/apps/frappe/frappe/utils/backups.py", line 195, in get_backup
    self.take_dump()
  File "/Users/andela/Dev/frappe-bench/apps/frappe/frappe/utils/backups.py", line 354, in take_dump
    frappe.throw(
  File "/Users/andela/Dev/frappe-bench/apps/frappe/frappe/__init__.py", line 427, in throw
    msgprint(msg, raise_exception=exc, title=title, indicator='red', is_minimizable=is_minimizable, wide=wide, as_list=as_list)
  File "/Users/andela/Dev/frappe-bench/apps/frappe/frappe/__init__.py", line 406, in msgprint
    _raise_exception()
  File "/Users/andela/Dev/frappe-bench/apps/frappe/frappe/__init__.py", line 360, in _raise_exception
    raise raise_exception(msg)
frappe.exceptions.ExecutableNotFound: mysqldump not found in PATH! This is required to take a backup.

File ./contacts_test/private/backups/20210505_150938-contacts_test-database.sql.gz is recent
File ./contacts_test/private/backups/20210505_150938-contacts_test-site_config_backup.json is recent
Backup failed for Site library-test0. Database or site_config.json may be corrupted
Traceback (most recent call last):
  File "/Users/andela/Dev/frappe-bench/apps/frappe/frappe/commands/site.py", line 429, in backup
    odb = scheduled_backup(
  File "/Users/andela/Dev/frappe-bench/apps/frappe/frappe/utils/backups.py", line 515, in scheduled_backup
    odb = new_backup(
  File "/Users/andela/Dev/frappe-bench/apps/frappe/frappe/utils/backups.py", line 567, in new_backup
    odb.get_backup(older_than, ignore_files, force=force)
  File "/Users/andela/Dev/frappe-bench/apps/frappe/frappe/utils/backups.py", line 195, in get_backup
    self.take_dump()
  File "/Users/andela/Dev/frappe-bench/apps/frappe/frappe/utils/backups.py", line 354, in take_dump
    frappe.throw(
  File "/Users/andela/Dev/frappe-bench/apps/frappe/frappe/__init__.py", line 427, in throw
    msgprint(msg, raise_exception=exc, title=title, indicator='red', is_minimizable=is_minimizable, wide=wide, as_list=as_list)
  File "/Users/andela/Dev/frappe-bench/apps/frappe/frappe/__init__.py", line 406, in msgprint
    _raise_exception()
  File "/Users/andela/Dev/frappe-bench/apps/frappe/frappe/__init__.py", line 360, in _raise_exception
    raise raise_exception(msg)
frappe.exceptions.ExecutableNotFound: mysqldump not found in PATH! This is required to take a backup.

Backup failed for Site contacts_test. Database or site_config.json may be corrupted
Backup failed for Site contacts_test. Database or site_config.json may be corrupted
Traceback (most recent call last):
  File "/Users/andela/Dev/frappe-bench/apps/frappe/frappe/commands/site.py", line 429, in backup
    odb = scheduled_backup(
  File "/Users/andela/Dev/frappe-bench/apps/frappe/frappe/utils/backups.py", line 515, in scheduled_backup
    odb = new_backup(
  File "/Users/andela/Dev/frappe-bench/apps/frappe/frappe/utils/backups.py", line 548, in new_backup
    delete_temp_backups()
  File "/Users/andela/Dev/frappe-bench/apps/frappe/frappe/utils/backups.py", line 582, in delete_temp_backups
    os.remove(this_file_path)
FileNotFoundError: [Errno 2] No such file or directory: './contacts_test/private/backups/20210505_150938-contacts_test-site_config_backup.json'

Backup failed for Site library-test0. Database or site_config.json may be corrupted
Traceback (most recent call last):
  File "/Users/andela/Dev/frappe-bench/apps/frappe/frappe/commands/site.py", line 429, in backup
    odb = scheduled_backup(
  File "/Users/andela/Dev/frappe-bench/apps/frappe/frappe/utils/backups.py", line 515, in scheduled_backup
    odb = new_backup(
  File "/Users/andela/Dev/frappe-bench/apps/frappe/frappe/utils/backups.py", line 567, in new_backup
    odb.get_backup(older_than, ignore_files, force=force)
  File "/Users/andela/Dev/frappe-bench/apps/frappe/frappe/utils/backups.py", line 195, in get_backup
    self.take_dump()
  File "/Users/andela/Dev/frappe-bench/apps/frappe/frappe/utils/backups.py", line 354, in take_dump
    frappe.throw(
  File "/Users/andela/Dev/frappe-bench/apps/frappe/frappe/__init__.py", line 427, in throw
    msgprint(msg, raise_exception=exc, title=title, indicator='red', is_minimizable=is_minimizable, wide=wide, as_list=as_list)
  File "/Users/andela/Dev/frappe-bench/apps/frappe/frappe/__init__.py", line 406, in msgprint
    _raise_exception()
  File "/Users/andela/Dev/frappe-bench/apps/frappe/frappe/__init__.py", line 360, in _raise_exception
    raise raise_exception(msg)
frappe.exceptions.ExecutableNotFound: mysqldump not found in PATH! This is required to take a backup.

Traceback (most recent call last):
  File "/Users/andela/Dev/frappe-bench/apps/frappe/frappe/commands/site.py", line 429, in backup
    odb = scheduled_backup(
  File "/Users/andela/Dev/frappe-bench/apps/frappe/frappe/utils/backups.py", line 515, in scheduled_backup
    odb = new_backup(
  File "/Users/andela/Dev/frappe-bench/apps/frappe/frappe/utils/backups.py", line 567, in new_backup
    odb.get_backup(older_than, ignore_files, force=force)
  File "/Users/andela/Dev/frappe-bench/apps/frappe/frappe/utils/backups.py", line 195, in get_backup
    self.take_dump()
  File "/Users/andela/Dev/frappe-bench/apps/frappe/frappe/utils/backups.py", line 354, in take_dump
    frappe.throw(
  File "/Users/andela/Dev/frappe-bench/apps/frappe/frappe/__init__.py", line 427, in throw
    msgprint(msg, raise_exception=exc, title=title, indicator='red', is_minimizable=is_minimizable, wide=wide, as_list=as_list)
  File "/Users/andela/Dev/frappe-bench/apps/frappe/frappe/__init__.py", line 406, in msgprint
    _raise_exception()
  File "/Users/andela/Dev/frappe-bench/apps/frappe/frappe/__init__.py", line 360, in _raise_exception
    raise raise_exception(msg)
frappe.exceptions.ExecutableNotFound: mysqldump not found in PATH! This is required to take a backup.

Backup failed for Site library-test0. Database or site_config.json may be corrupted
Traceback (most recent call last):
  File "/Users/andela/Dev/frappe-bench/apps/frappe/frappe/commands/site.py", line 429, in backup
    odb = scheduled_backup(
  File "/Users/andela/Dev/frappe-bench/apps/frappe/frappe/utils/backups.py", line 515, in scheduled_backup
    odb = new_backup(
  File "/Users/andela/Dev/frappe-bench/apps/frappe/frappe/utils/backups.py", line 567, in new_backup
    odb.get_backup(older_than, ignore_files, force=force)
  File "/Users/andela/Dev/frappe-bench/apps/frappe/frappe/utils/backups.py", line 195, in get_backup
    self.take_dump()
  File "/Users/andela/Dev/frappe-bench/apps/frappe/frappe/utils/backups.py", line 354, in take_dump
    frappe.throw(
  File "/Users/andela/Dev/frappe-bench/apps/frappe/frappe/__init__.py", line 427, in throw
    msgprint(msg, raise_exception=exc, title=title, indicator='red', is_minimizable=is_minimizable, wide=wide, as_list=as_list)
  File "/Users/andela/Dev/frappe-bench/apps/frappe/frappe/__init__.py", line 406, in msgprint
    _raise_exception()
  File "/Users/andela/Dev/frappe-bench/apps/frappe/frappe/__init__.py", line 360, in _raise_exception
    raise raise_exception(msg)
frappe.exceptions.ExecutableNotFound: mysqldump not found in PATH! This is required to take a backup.

Backup failed for Site companies. Database or site_config.json may be corrupted
Backup failed for Site companies. Database or site_config.json may be corrupted
Traceback (most recent call last):
  File "/Users/andela/Dev/frappe-bench/apps/frappe/frappe/commands/site.py", line 429, in backup
    odb = scheduled_backup(
  File "/Users/andela/Dev/frappe-bench/apps/frappe/frappe/utils/backups.py", line 515, in scheduled_backup
    odb = new_backup(
  File "/Users/andela/Dev/frappe-bench/apps/frappe/frappe/utils/backups.py", line 567, in new_backup
    odb.get_backup(older_than, ignore_files, force=force)
  File "/Users/andela/Dev/frappe-bench/apps/frappe/frappe/utils/backups.py", line 195, in get_backup
    self.take_dump()
  File "/Users/andela/Dev/frappe-bench/apps/frappe/frappe/utils/backups.py", line 354, in take_dump
    frappe.throw(
  File "/Users/andela/Dev/frappe-bench/apps/frappe/frappe/__init__.py", line 427, in throw
    msgprint(msg, raise_exception=exc, title=title, indicator='red', is_minimizable=is_minimizable, wide=wide, as_list=as_list)
  File "/Users/andela/Dev/frappe-bench/apps/frappe/frappe/__init__.py", line 406, in msgprint
    _raise_exception()
  File "/Users/andela/Dev/frappe-bench/apps/frappe/frappe/__init__.py", line 360, in _raise_exception
    raise raise_exception(msg)
frappe.exceptions.ExecutableNotFound: mysqldump not found in PATH! This is required to take a backup.

Backup failed for Site contacts_test. Database or site_config.json may be corrupted
Traceback (most recent call last):
  File "/Users/andela/Dev/frappe-bench/apps/frappe/frappe/commands/site.py", line 429, in backup
    odb = scheduled_backup(
  File "/Users/andela/Dev/frappe-bench/apps/frappe/frappe/utils/backups.py", line 515, in scheduled_backup
    odb = new_backup(
  File "/Users/andela/Dev/frappe-bench/apps/frappe/frappe/utils/backups.py", line 567, in new_backup
    odb.get_backup(older_than, ignore_files, force=force)
  File "/Users/andela/Dev/frappe-bench/apps/frappe/frappe/utils/backups.py", line 195, in get_backup
    self.take_dump()
  File "/Users/andela/Dev/frappe-bench/apps/frappe/frappe/utils/backups.py", line 354, in take_dump
    frappe.throw(
  File "/Users/andela/Dev/frappe-bench/apps/frappe/frappe/__init__.py", line 427, in throw
    msgprint(msg, raise_exception=exc, title=title, indicator='red', is_minimizable=is_minimizable, wide=wide, as_list=as_list)
  File "/Users/andela/Dev/frappe-bench/apps/frappe/frappe/__init__.py", line 406, in msgprint
    _raise_exception()
  File "/Users/andela/Dev/frappe-bench/apps/frappe/frappe/__init__.py", line 360, in _raise_exception
    raise raise_exception(msg)
frappe.exceptions.ExecutableNotFound: mysqldump not found in PATH! This is required to take a backup.

Backup failed for Site contacts_test. Database or site_config.json may be corrupted
Traceback (most recent call last):
  File "/Users/andela/Dev/frappe-bench/apps/frappe/frappe/commands/site.py", line 429, in backup
    odb = scheduled_backup(
  File "/Users/andela/Dev/frappe-bench/apps/frappe/frappe/utils/backups.py", line 515, in scheduled_backup
    odb = new_backup(
  File "/Users/andela/Dev/frappe-bench/apps/frappe/frappe/utils/backups.py", line 567, in new_backup
    odb.get_backup(older_than, ignore_files, force=force)
  File "/Users/andela/Dev/frappe-bench/apps/frappe/frappe/utils/backups.py", line 195, in get_backup
    self.take_dump()
  File "/Users/andela/Dev/frappe-bench/apps/frappe/frappe/utils/backups.py", line 354, in take_dump
    frappe.throw(
  File "/Users/andela/Dev/frappe-bench/apps/frappe/frappe/__init__.py", line 427, in throw
    msgprint(msg, raise_exception=exc, title=title, indicator='red', is_minimizable=is_minimizable, wide=wide, as_list=as_list)
  File "/Users/andela/Dev/frappe-bench/apps/frappe/frappe/__init__.py", line 406, in msgprint
    _raise_exception()
  File "/Users/andela/Dev/frappe-bench/apps/frappe/frappe/__init__.py", line 360, in _raise_exception
    raise raise_exception(msg)
frappe.exceptions.ExecutableNotFound: mysqldump not found in PATH! This is required to take a backup.

Backup failed for Site library-test0. Database or site_config.json may be corrupted
Traceback (most recent call last):
  File "/Users/andela/Dev/frappe-bench/apps/frappe/frappe/commands/site.py", line 429, in backup
    odb = scheduled_backup(
  File "/Users/andela/Dev/frappe-bench/apps/frappe/frappe/utils/backups.py", line 515, in scheduled_backup
    odb = new_backup(
  File "/Users/andela/Dev/frappe-bench/apps/frappe/frappe/utils/backups.py", line 567, in new_backup
    odb.get_backup(older_than, ignore_files, force=force)
  File "/Users/andela/Dev/frappe-bench/apps/frappe/frappe/utils/backups.py", line 195, in get_backup
    self.take_dump()
  File "/Users/andela/Dev/frappe-bench/apps/frappe/frappe/utils/backups.py", line 354, in take_dump
    frappe.throw(
  File "/Users/andela/Dev/frappe-bench/apps/frappe/frappe/__init__.py", line 427, in throw
    msgprint(msg, raise_exception=exc, title=title, indicator='red', is_minimizable=is_minimizable, wide=wide, as_list=as_list)
  File "/Users/andela/Dev/frappe-bench/apps/frappe/frappe/__init__.py", line 406, in msgprint
    _raise_exception()
  File "/Users/andela/Dev/frappe-bench/apps/frappe/frappe/__init__.py", line 360, in _raise_exception
    raise raise_exception(msg)
frappe.exceptions.ExecutableNotFound: mysqldump not found in PATH! This is required to take a backup.

Traceback (most recent call last):
  File "/Users/andela/Dev/frappe-bench/apps/frappe/frappe/commands/site.py", line 429, in backup
    odb = scheduled_backup(
  File "/Users/andela/Dev/frappe-bench/apps/frappe/frappe/utils/backups.py", line 515, in scheduled_backup
    odb = new_backup(
  File "/Users/andela/Dev/frappe-bench/apps/frappe/frappe/utils/backups.py", line 567, in new_backup
    odb.get_backup(older_than, ignore_files, force=force)
  File "/Users/andela/Dev/frappe-bench/apps/frappe/frappe/utils/backups.py", line 195, in get_backup
    self.take_dump()
  File "/Users/andela/Dev/frappe-bench/apps/frappe/frappe/utils/backups.py", line 354, in take_dump
    frappe.throw(
  File "/Users/andela/Dev/frappe-bench/apps/frappe/frappe/__init__.py", line 427, in throw
    msgprint(msg, raise_exception=exc, title=title, indicator='red', is_minimizable=is_minimizable, wide=wide, as_list=as_list)
  File "/Users/andela/Dev/frappe-bench/apps/frappe/frappe/__init__.py", line 406, in msgprint
    _raise_exception()
  File "/Users/andela/Dev/frappe-bench/apps/frappe/frappe/__init__.py", line 360, in _raise_exception
    raise raise_exception(msg)
frappe.exceptions.ExecutableNotFound: mysqldump not found in PATH! This is required to take a backup.

Backup failed for Site library-test0. Database or site_config.json may be corrupted
Traceback (most recent call last):
  File "/Users/andela/Dev/frappe-bench/apps/frappe/frappe/commands/site.py", line 429, in backup
    odb = scheduled_backup(
  File "/Users/andela/Dev/frappe-bench/apps/frappe/frappe/utils/backups.py", line 515, in scheduled_backup
    odb = new_backup(
  File "/Users/andela/Dev/frappe-bench/apps/frappe/frappe/utils/backups.py", line 567, in new_backup
    odb.get_backup(older_than, ignore_files, force=force)
  File "/Users/andela/Dev/frappe-bench/apps/frappe/frappe/utils/backups.py", line 195, in get_backup
    self.take_dump()
  File "/Users/andela/Dev/frappe-bench/apps/frappe/frappe/utils/backups.py", line 354, in take_dump
    frappe.throw(
  File "/Users/andela/Dev/frappe-bench/apps/frappe/frappe/__init__.py", line 427, in throw
    msgprint(msg, raise_exception=exc, title=title, indicator='red', is_minimizable=is_minimizable, wide=wide, as_list=as_list)
  File "/Users/andela/Dev/frappe-bench/apps/frappe/frappe/__init__.py", line 406, in msgprint
    _raise_exception()
  File "/Users/andela/Dev/frappe-bench/apps/frappe/frappe/__init__.py", line 360, in _raise_exception
    raise raise_exception(msg)
frappe.exceptions.ExecutableNotFound: mysqldump not found in PATH! This is required to take a backup.

Backup failed for Site companies. Database or site_config.json may be corrupted
Backup failed for Site companies. Database or site_config.json may be corrupted
Traceback (most recent call last):
  File "/Users/andela/Dev/frappe-bench/apps/frappe/frappe/commands/site.py", line 429, in backup
    odb = scheduled_backup(
  File "/Users/andela/Dev/frappe-bench/apps/frappe/frappe/utils/backups.py", line 515, in scheduled_backup
    odb = new_backup(
  File "/Users/andela/Dev/frappe-bench/apps/frappe/frappe/utils/backups.py", line 567, in new_backup
    odb.get_backup(older_than, ignore_files, force=force)
  File "/Users/andela/Dev/frappe-bench/apps/frappe/frappe/utils/backups.py", line 195, in get_backup
    self.take_dump()
  File "/Users/andela/Dev/frappe-bench/apps/frappe/frappe/utils/backups.py", line 354, in take_dump
    frappe.throw(
  File "/Users/andela/Dev/frappe-bench/apps/frappe/frappe/__init__.py", line 427, in throw
    msgprint(msg, raise_exception=exc, title=title, indicator='red', is_minimizable=is_minimizable, wide=wide, as_list=as_list)
  File "/Users/andela/Dev/frappe-bench/apps/frappe/frappe/__init__.py", line 406, in msgprint
    _raise_exception()
  File "/Users/andela/Dev/frappe-bench/apps/frappe/frappe/__init__.py", line 360, in _raise_exception
    raise raise_exception(msg)
frappe.exceptions.ExecutableNotFound: mysqldump not found in PATH! This is required to take a backup.

Backup failed for Site contacts_test. Database or site_config.json may be corrupted
Traceback (most recent call last):
  File "/Users/andela/Dev/frappe-bench/apps/frappe/frappe/commands/site.py", line 429, in backup
    odb = scheduled_backup(
  File "/Users/andela/Dev/frappe-bench/apps/frappe/frappe/utils/backups.py", line 515, in scheduled_backup
    odb = new_backup(
  File "/Users/andela/Dev/frappe-bench/apps/frappe/frappe/utils/backups.py", line 567, in new_backup
    odb.get_backup(older_than, ignore_files, force=force)
  File "/Users/andela/Dev/frappe-bench/apps/frappe/frappe/utils/backups.py", line 195, in get_backup
    self.take_dump()
  File "/Users/andela/Dev/frappe-bench/apps/frappe/frappe/utils/backups.py", line 354, in take_dump
    frappe.throw(
  File "/Users/andela/Dev/frappe-bench/apps/frappe/frappe/__init__.py", line 427, in throw
    msgprint(msg, raise_exception=exc, title=title, indicator='red', is_minimizable=is_minimizable, wide=wide, as_list=as_list)
  File "/Users/andela/Dev/frappe-bench/apps/frappe/frappe/__init__.py", line 406, in msgprint
    _raise_exception()
  File "/Users/andela/Dev/frappe-bench/apps/frappe/frappe/__init__.py", line 360, in _raise_exception
    raise raise_exception(msg)
frappe.exceptions.ExecutableNotFound: mysqldump not found in PATH! This is required to take a backup.

Backup failed for Site contacts_test. Database or site_config.json may be corrupted
Traceback (most recent call last):
  File "/Users/andela/Dev/frappe-bench/apps/frappe/frappe/commands/site.py", line 429, in backup
    odb = scheduled_backup(
  File "/Users/andela/Dev/frappe-bench/apps/frappe/frappe/utils/backups.py", line 515, in scheduled_backup
    odb = new_backup(
  File "/Users/andela/Dev/frappe-bench/apps/frappe/frappe/utils/backups.py", line 567, in new_backup
    odb.get_backup(older_than, ignore_files, force=force)
  File "/Users/andela/Dev/frappe-bench/apps/frappe/frappe/utils/backups.py", line 195, in get_backup
    self.take_dump()
  File "/Users/andela/Dev/frappe-bench/apps/frappe/frappe/utils/backups.py", line 354, in take_dump
    frappe.throw(
  File "/Users/andela/Dev/frappe-bench/apps/frappe/frappe/__init__.py", line 427, in throw
    msgprint(msg, raise_exception=exc, title=title, indicator='red', is_minimizable=is_minimizable, wide=wide, as_list=as_list)
  File "/Users/andela/Dev/frappe-bench/apps/frappe/frappe/__init__.py", line 406, in msgprint
    _raise_exception()
  File "/Users/andela/Dev/frappe-bench/apps/frappe/frappe/__init__.py", line 360, in _raise_exception
    raise raise_exception(msg)
frappe.exceptions.ExecutableNotFound: mysqldump not found in PATH! This is required to take a backup.

Backup failed for Site library-test0. Database or site_config.json may be corrupted
Traceback (most recent call last):
  File "/Users/andela/Dev/frappe-bench/apps/frappe/frappe/commands/site.py", line 429, in backup
    odb = scheduled_backup(
  File "/Users/andela/Dev/frappe-bench/apps/frappe/frappe/utils/backups.py", line 515, in scheduled_backup
    odb = new_backup(
  File "/Users/andela/Dev/frappe-bench/apps/frappe/frappe/utils/backups.py", line 567, in new_backup
    odb.get_backup(older_than, ignore_files, force=force)
  File "/Users/andela/Dev/frappe-bench/apps/frappe/frappe/utils/backups.py", line 195, in get_backup
    self.take_dump()
  File "/Users/andela/Dev/frappe-bench/apps/frappe/frappe/utils/backups.py", line 354, in take_dump
    frappe.throw(
  File "/Users/andela/Dev/frappe-bench/apps/frappe/frappe/__init__.py", line 427, in throw
    msgprint(msg, raise_exception=exc, title=title, indicator='red', is_minimizable=is_minimizable, wide=wide, as_list=as_list)
  File "/Users/andela/Dev/frappe-bench/apps/frappe/frappe/__init__.py", line 406, in msgprint
    _raise_exception()
  File "/Users/andela/Dev/frappe-bench/apps/frappe/frappe/__init__.py", line 360, in _raise_exception
    raise raise_exception(msg)
frappe.exceptions.ExecutableNotFound: mysqldump not found in PATH! This is required to take a backup.

Backup failed for Site library-test0. Database or site_config.json may be corrupted
Traceback (most recent call last):
  File "/Users/andela/Dev/frappe-bench/apps/frappe/frappe/commands/site.py", line 429, in backup
    odb = scheduled_backup(
  File "/Users/andela/Dev/frappe-bench/apps/frappe/frappe/utils/backups.py", line 515, in scheduled_backup
    odb = new_backup(
  File "/Users/andela/Dev/frappe-bench/apps/frappe/frappe/utils/backups.py", line 567, in new_backup
    odb.get_backup(older_than, ignore_files, force=force)
  File "/Users/andela/Dev/frappe-bench/apps/frappe/frappe/utils/backups.py", line 195, in get_backup
    self.take_dump()
  File "/Users/andela/Dev/frappe-bench/apps/frappe/frappe/utils/backups.py", line 354, in take_dump
    frappe.throw(
  File "/Users/andela/Dev/frappe-bench/apps/frappe/frappe/__init__.py", line 427, in throw
    msgprint(msg, raise_exception=exc, title=title, indicator='red', is_minimizable=is_minimizable, wide=wide, as_list=as_list)
  File "/Users/andela/Dev/frappe-bench/apps/frappe/frappe/__init__.py", line 406, in msgprint
    _raise_exception()
  File "/Users/andela/Dev/frappe-bench/apps/frappe/frappe/__init__.py", line 360, in _raise_exception
    raise raise_exception(msg)
frappe.exceptions.ExecutableNotFound: mysqldump not found in PATH! This is required to take a backup.

Traceback (most recent call last):
  File "/Users/andela/Dev/frappe-bench/apps/frappe/frappe/commands/site.py", line 429, in backup
    odb = scheduled_backup(
  File "/Users/andela/Dev/frappe-bench/apps/frappe/frappe/utils/backups.py", line 515, in scheduled_backup
    odb = new_backup(
  File "/Users/andela/Dev/frappe-bench/apps/frappe/frappe/utils/backups.py", line 567, in new_backup
    odb.get_backup(older_than, ignore_files, force=force)
  File "/Users/andela/Dev/frappe-bench/apps/frappe/frappe/utils/backups.py", line 195, in get_backup
    self.take_dump()
  File "/Users/andela/Dev/frappe-bench/apps/frappe/frappe/utils/backups.py", line 354, in take_dump
    frappe.throw(
  File "/Users/andela/Dev/frappe-bench/apps/frappe/frappe/__init__.py", line 427, in throw
    msgprint(msg, raise_exception=exc, title=title, indicator='red', is_minimizable=is_minimizable, wide=wide, as_list=as_list)
  File "/Users/andela/Dev/frappe-bench/apps/frappe/frappe/__init__.py", line 406, in msgprint
    _raise_exception()
  File "/Users/andela/Dev/frappe-bench/apps/frappe/frappe/__init__.py", line 360, in _raise_exception
    raise raise_exception(msg)
frappe.exceptions.ExecutableNotFound: mysqldump not found in PATH! This is required to take a backup.

